Workbook

Sheet Dashboard
A1: VODAFONE–VOIS INTELLIGENT AI ASSISTANT
A2: Executive Project Dashboard · Enterprise GenAI · RAG · MCP on Microsoft Azure AI Foundry
A3: ="Status as at "&TEXT(StatusDate,"dd mmm yyyy")&" · Week "&(INT((StatusDate-ProjectStart)/7)+1)&" of 20 · PM: Ananya Rao · Sponsor: Rajesh Menon" -> Status as at 15 Jan 2027 · Week 13 of 20 · PM: Ananya Rao · Sponsor: Rajesh Menon
A5: OVERALL PROGRESS | E5: SCHEDULE PERFORMANCE (SPI) | I5: COST PERFORMANCE (CPI) | M5: BUDGET AT COMPLETION | Q5: MILESTONES ACHIEVED | U5: OVERALL RAG
A6: ='WBS Schedule'!K7 -> 0.53424242 | E6: =IF('WBS Schedule'!Q7=0,1,'WBS Schedule'!R7/'WBS Schedule'!Q7) -> 0.94278075 | I6: =IF('WBS Schedule'!S7=0,1,'WBS Schedule'!R7/'WBS Schedule'!S7) -> 0.96240191 | M6: ='WBS Schedule'!P7 -> 105.6 | Q6: =COUNT(Milestones!F5:F9)&" / 5" -> 2 / 5 | U6: =IF(OR(IF('WBS Schedule'!Q7=0,1,'WBS Schedule'!R7/'WBS Schedule'!Q7)<0.9,IF('WBS Schedule'!S7=0,1,'WBS Schedule'!R7/'WBS Schedule'!S7)<0.9),"RED",IF(OR(IF('WBS Schedule'!Q7=0,1,'WBS Schedule'!R7/'WBS Schedule'!Q7)<0.97,IF('WBS Schedule'!S7=0,1,'WBS Schedule'!R7/'WBS Schedule'!S7)<0.97),"AMBER","GREEN")) -> AMBER
A7: ="Planned: "&TEXT('WBS Schedule'!J7,"0%") -> Planned: 57% | E7: =IF(IF('WBS Schedule'!Q7=0,1,'WBS Schedule'!R7/'WBS Schedule'!Q7)>=0.97,"On schedule",IF(IF('WBS Schedule'!Q7=0,1,'WBS Schedule'!R7/'WBS Schedule'!Q7)>=0.9,"Slightly behind","Behind schedule")) -> Slightly behind | I7: =IF(IF('WBS Schedule'!S7=0,1,'WBS Schedule'!R7/'WBS Schedule'!S7)>=0.97,"Within budget",IF(IF('WBS Schedule'!S7=0,1,'WBS Schedule'!R7/'WBS Schedule'!S7)>=0.9,"Minor overrun","Over budget")) -> Minor overrun | M7: ="EAC: ₹"&TEXT('WBS Schedule'!P7/IF('WBS Schedule'!S7=0,1,'WBS Schedule'!R7/'WBS Schedule'!S7),"#,##0.0")&" L" -> EAC: ₹109.7 L | Q7: ="Next: "&INDEX(Milestones!B5:B9,MATCH("",Milestones!F5:F9&"",0)) -> Next: Application integrations | U7: Based on SPI & CPI thresholds
A9: FORECAST FINISH | E9: WORKING DAYS ELAPSED | I9: ACTIVITIES COMPLETE | M9: BEHIND / OVERDUE | Q9: OPEN HIGH RISKS | U9: COST VARIANCE (CV)
A10: =Milestones!E9 -> 46458 | E10: =NETWORKDAYS(ProjectStart,StatusDate,Holidays) -> 61 | I10: =COUNTIFS('WBS Schedule'!$B$7:$B$68,2,'WBS Schedule'!$G$7:$G$68,">0",'WBS Schedule'!$M$7:$M$68,"Complete") -> 27 | M10: =COUNTIFS('WBS Schedule'!$B$7:$B$68,2,'WBS Schedule'!$M$7:$M$68,"Behind")+COUNTIFS('WBS Schedule'!$B$7:$B$68,2,'WBS Schedule'!$M$7:$M$68,"Overdue") -> 5 | Q10: ='Chart Data'!B46 -> 2 | U10: ='WBS Schedule'!R7-'WBS Schedule'!S7 -> -2.204
A11: ="Baseline: "&TEXT(Milestones!D9,"dd-mmm-yy") -> Baseline: 12-Mar-27 | E11: ="of "&'WBS Schedule'!G7&" total · "&TEXT(NETWORKDAYS(ProjectStart,StatusDate,Holidays)/'WBS Schedule'!G7,"0%") -> of 100 total · 61% | I11: ="of "&COUNTIFS('WBS Schedule'!$B$7:$B$68,2,'WBS Schedule'!$G$7:$G$68,">0")&" activities" -> of 51 activities | M11: Activities needing attention | Q11: ="of "&COUNTIFS('RAID Log'!B5:B22,"Risk",'RAID Log'!K5:K22,"<>Closed")&" active risks" -> of 10 active risks | U11: ="EV ₹"&TEXT('WBS Schedule'!R7,"0.0")&" L vs AC ₹"&TEXT('WBS Schedule'!S7,"0.0")&" L" -> EV ₹56.4 L vs AC ₹58.6 L
A13: KEY HIGHLIGHTS | M13: ISSUES, RISKS & ACTIONS
A14: ✔ M1 Architecture approved and M2 AI Assistant MVP delivered | M14: ✖ Oracle sandbox access delayed ~2 weeks — M3 re-forecast; escalated to sponsor
A15: ✔ Foundry IQ retrieval at 88% recall@5 on a 250-question benchmark (target 85%) | M15: ✖ SAP connector effort over estimate — CPI below 1.0; recovery plan in Month 4
A16: ✔ SAP and QA/testing connectors running end-to-end in non-production | M16: ! GPT-5 TPM quota limits load tests — increase requested with Microsoft
A17: ✔ P95 response time 6.4 s at 50 concurrent users (target ≤ 8 s) | M17: ! Groundedness 87% vs 90% target — prompt & citation tuning in sprint S7
A18: ► Next 2 weeks: Entra ID RBAC, authorization rules, AI evaluation sprint | M18: ► Decision needed: approve 1-week M3 slip or descope Oracle write-back demo
A20: 1 · EARNED VALUE — PV vs EV vs AC | M20: 2 · PERFORMANCE INDICES TREND
A40: 3 · PHASE TIMELINE | M40: 4 · PHASE PROGRESS
A60: 5 · COST PERFORMANCE | M60: 6 · ACTIVITY STATUS
A80: 7 · RESOURCE LOADING | M80: 8 · BURNDOWN
A100: 9 · AI QUALITY KPIs | M100: 10 · RAID SUMMARY
A120: 11 · RISK EXPOSURE | M120: 12 · RISK RATING MIX
A140: 13 · RISK HEAT MAP (count of active risks) | M140: 14 · MILESTONE TRACKER
A141: Probability ↓ / Impact → | C141: 1 | E141: 2 | G141: 3 | I141: 4 | K141: 5 | M141: ID | N141: Milestone | R141: Baseline | T141: Forecast | V141: Status | X141: Var (d)
A142: 5 | C142: =COUNTIFS('RAID Log'!$B$5:$B$22,"Risk",'RAID Log'!$E$5:$E$22,5,'RAID Log'!$F$5:$F$22,1,'RAID Log'!$K$5:$K$22,"<>Closed") -> 0 | E142: =COUNTIFS('RAID Log'!$B$5:$B$22,"Risk",'RAID Log'!$E$5:$E$22,5,'RAID Log'!$F$5:$F$22,2,'RAID Log'!$K$5:$K$22,"<>Closed") -> 0 | G142: =COUNTIFS('RAID Log'!$B$5:$B$22,"Risk",'RAID Log'!$E$5:$E$22,5,'RAID Log'!$F$5:$F$22,3,'RAID Log'!$K$5:$K$22,"<>Closed") -> 0 | I142: =COUNTIFS('RAID Log'!$B$5:$B$22,"Risk",'RAID Log'!$E$5:$E$22,5,'RAID Log'!$F$5:$F$22,4,'RAID Log'!$K$5:$K$22,"<>Closed") -> 0 | K142: =COUNTIFS('RAID Log'!$B$5:$B$22,"Risk",'RAID Log'!$E$5:$E$22,5,'RAID Log'!$F$5:$F$22,5,'RAID Log'!$K$5:$K$22,"<>Closed") -> 0 | M142: =Milestones!A5 -> M1 | N142: =Milestones!B5 -> Architecture approved | R142: =Milestones!D5 -> 46342 | T142: =IF(Milestones!F5<>"",Milestones!F5,Milestones!E5) -> 46342 | V142: =Milestones!H5 -> Achieved | X142: =Milestones!G5 -> 0
A143: 4 | C143: =COUNTIFS('RAID Log'!$B$5:$B$22,"Risk",'RAID Log'!$E$5:$E$22,4,'RAID Log'!$F$5:$F$22,1,'RAID Log'!$K$5:$K$22,"<>Closed") -> 0 | E143: =COUNTIFS('RAID Log'!$B$5:$B$22,"Risk",'RAID Log'!$E$5:$E$22,4,'RAID Log'!$F$5:$F$22,2,'RAID Log'!$K$5:$K$22,"<>Closed") -> 0 | G143: =COUNTIFS('RAID Log'!$B$5:$B$22,"Risk",'RAID Log'!$E$5:$E$22,4,'RAID Log'!$F$5:$F$22,3,'RAID Log'!$K$5:$K$22,"<>Closed") -> 1 | I143: =COUNTIFS('RAID Log'!$B$5:$B$22,"Risk",'RAID Log'!$E$5:$E$22,4,'RAID Log'!$F$5:$F$22,4,'RAID Log'!$K$5:$K$22,"<>Closed") -> 0 | K143: =COUNTIFS('RAID Log'!$B$5:$B$22,"Risk",'RAID Log'!$E$5:$E$22,4,'RAID Log'!$F$5:$F$22,5,'RAID Log'!$K$5:$K$22,"<>Closed") -> 1 | M143: =Milestones!A6 -> M2 | N143: =Milestones!B6 -> AI assistant MVP | R143: =Milestones!D6 -> 46371 | T143: =IF(Milestones!F6<>"",Milestones!F6,Milestones!E6) -> 46370 | V143: =Milestones!H6 -> Achieved | X143: =Milestones!G6 -> -1
A144: 3 | C144: =COUNTIFS('RAID Log'!$B$5:$B$22,"Risk",'RAID Log'!$E$5:$E$22,3,'RAID Log'!$F$5:$F$22,1,'RAID Log'!$K$5:$K$22,"<>Closed") -> 0 | E144: =COUNTIFS('RAID Log'!$B$5:$B$22,"Risk",'RAID Log'!$E$5:$E$22,3,'RAID Log'!$F$5:$F$22,2,'RAID Log'!$K$5:$K$22,"<>Closed") -> 0 | G144: =COUNTIFS('RAID Log'!$B$5:$B$22,"Risk",'RAID Log'!$E$5:$E$22,3,'RAID Log'!$F$5:$F$22,3,'RAID Log'!$K$5:$K$22,"<>Closed") -> 0 | I144: =COUNTIFS('RAID Log'!$B$5:$B$22,"Risk",'RAID Log'!$E$5:$E$22,3,'RAID Log'!$F$5:$F$22,4,'RAID Log'!$K$5:$K$22,"<>Closed") -> 3 | K144: =COUNTIFS('RAID Log'!$B$5:$B$22,"Risk",'RAID Log'!$E$5:$E$22,3,'RAID Log'!$F$5:$F$22,5,'RAID Log'!$K$5:$K$22,"<>Closed") -> 1 | M144: =Milestones!A7 -> M3 | N144: =Milestones!B7 -> Application integrations | R144: =Milestones!D7 -> 46401 | T144: =IF(Milestones!F7<>"",Milestones!F7,Milestones!E7) -> 46409 | V144: =Milestones!H7 -> At Risk | X144: =Milestones!G7 -> 6
A145: 2 | C145: =COUNTIFS('RAID Log'!$B$5:$B$22,"Risk",'RAID Log'!$E$5:$E$22,2,'RAID Log'!$F$5:$F$22,1,'RAID Log'!$K$5:$K$22,"<>Closed") -> 0 | E145: =COUNTIFS('RAID Log'!$B$5:$B$22,"Risk",'RAID Log'!$E$5:$E$22,2,'RAID Log'!$F$5:$F$22,2,'RAID Log'!$K$5:$K$22,"<>Closed") -> 0 | G145: =COUNTIFS('RAID Log'!$B$5:$B$22,"Risk",'RAID Log'!$E$5:$E$22,2,'RAID Log'!$F$5:$F$22,3,'RAID Log'!$K$5:$K$22,"<>Closed") -> 2 | I145: =COUNTIFS('RAID Log'!$B$5:$B$22,"Risk",'RAID Log'!$E$5:$E$22,2,'RAID Log'!$F$5:$F$22,4,'RAID Log'!$K$5:$K$22,"<>Closed") -> 1 | K145: =COUNTIFS('RAID Log'!$B$5:$B$22,"Risk",'RAID Log'!$E$5:$E$22,2,'RAID Log'!$F$5:$F$22,5,'RAID Log'!$K$5:$K$22,"<>Closed") -> 1 | M145: =Milestones!A8 -> M4 | N145: =Milestones!B8 -> Release candidate | R145: =Milestones!D8 -> 46430 | T145: =IF(Milestones!F8<>"",Milestones!F8,Milestones!E8) -> 46434 | V145: =Milestones!H8 -> At Risk | X145: =Milestones!G8 -> 2
A146: 1 | C146: =COUNTIFS('RAID Log'!$B$5:$B$22,"Risk",'RAID Log'!$E$5:$E$22,1,'RAID Log'!$F$5:$F$22,1,'RAID Log'!$K$5:$K$22,"<>Closed") -> 0 | E146: =COUNTIFS('RAID Log'!$B$5:$B$22,"Risk",'RAID Log'!$E$5:$E$22,1,'RAID Log'!$F$5:$F$22,2,'RAID Log'!$K$5:$K$22,"<>Closed") -> 0 | G146: =COUNTIFS('RAID Log'!$B$5:$B$22,"Risk",'RAID Log'!$E$5:$E$22,1,'RAID Log'!$F$5:$F$22,3,'RAID Log'!$K$5:$K$22,"<>Closed") -> 0 | I146: =COUNTIFS('RAID Log'!$B$5:$B$22,"Risk",'RAID Log'!$E$5:$E$22,1,'RAID Log'!$F$5:$F$22,4,'RAID Log'!$K$5:$K$22,"<>Closed") -> 0 | K146: =COUNTIFS('RAID Log'!$B$5:$B$22,"Risk",'RAID Log'!$E$5:$E$22,1,'RAID Log'!$F$5:$F$22,5,'RAID Log'!$K$5:$K$22,"<>Closed") -> 0 | M146: =Milestones!A9 -> M5 | N146: =Milestones!B9 -> Pilot accepted | R146: =Milestones!D9 -> 46458 | T146: =IF(Milestones!F9<>"",Milestones!F9,Milestones!E9) -> 46458 | V146: =Milestones!H9 -> On Track | X146: =Milestones!G9 -> 0
A149: 15 · PHASE SUMMARY
A150: Phase | F150: Start | H150: Finish | J150: Budget ₹ L | L150: EV ₹ L | N150: AC ₹ L | P150: CPI | R150: Planned % | T150: Actual % | V150: Status
A151: M1 Discovery | F151: ='WBS Schedule'!H8 -> 46314 | H151: ='WBS Schedule'!I8 -> 46342 | J151: ='WBS Schedule'!P8 -> 16.96 | L151: ='WBS Schedule'!R8 -> 16.96 | N151: ='WBS Schedule'!S8 -> 16.26 | P151: =IF('WBS Schedule'!S8=0,1,'WBS Schedule'!R8/'WBS Schedule'!S8) -> 1.0430504 | R151: ='WBS Schedule'!J8 -> 1 | T151: ='WBS Schedule'!K8 -> 1 | V151: ='WBS Schedule'!M8 -> Complete
A152: M2 AI Foundation | F152: ='WBS Schedule'!H20 -> 46343 | H152: ='WBS Schedule'!I20 -> 46371 | J152: ='WBS Schedule'!P20 -> 17.28 | L152: ='WBS Schedule'!R20 -> 17.28 | N152: ='WBS Schedule'!S20 -> 17.9 | P152: =IF('WBS Schedule'!S20=0,1,'WBS Schedule'!R20/'WBS Schedule'!S20) -> 0.96536313 | R152: ='WBS Schedule'!J20 -> 1 | T152: ='WBS Schedule'!K20 -> 1 | V152: ='WBS Schedule'!M20 -> Complete
A153: M3 Integration | F153: ='WBS Schedule'!H32 -> 46372 | H153: ='WBS Schedule'!I32 -> 46401 | J153: ='WBS Schedule'!P32 -> 23.68 | L153: ='WBS Schedule'!R32 -> 20 | N153: ='WBS Schedule'!S32 -> 22.28 | P153: =IF('WBS Schedule'!S32=0,1,'WBS Schedule'!R32/'WBS Schedule'!S32) -> 0.89766607 | R153: ='WBS Schedule'!J32 -> 1 | T153: ='WBS Schedule'!K32 -> 0.84459459 | V153: ='WBS Schedule'!M32 -> Overdue
A154: M4 Security & QA | F154: ='WBS Schedule'!H44 -> 46402 | H154: ='WBS Schedule'!I44 -> 46430 | J154: ='WBS Schedule'!P44 -> 23.68 | L154: ='WBS Schedule'!R44 -> 2.176 | N154: ='WBS Schedule'!S44 -> 2.18 | P154: =IF('WBS Schedule'!S44=0,1,'WBS Schedule'!R44/'WBS Schedule'!S44) -> 0.99816514 | R154: ='WBS Schedule'!J44 -> 0.081081081 | T154: ='WBS Schedule'!K44 -> 0.091891892 | V154: ='WBS Schedule'!M44 -> In Progress
A155: M5 Pilot & Handover | F155: ='WBS Schedule'!H56 -> 46433 | H155: ='WBS Schedule'!I56 -> 46458 | J155: ='WBS Schedule'!P56 -> 24 | L155: ='WBS Schedule'!R56 -> 0 | N155: ='WBS Schedule'!S56 -> 0 | P155: =IF('WBS Schedule'!S56=0,1,'WBS Schedule'!R56/'WBS Schedule'!S56) -> 1 | R155: ='WBS Schedule'!J56 -> 0 | T155: ='WBS Schedule'!K56 -> 0 | V155: ='WBS Schedule'!M56 -> Not Started
A156: Total project | F156: ='WBS Schedule'!H7 -> 46314 | H156: ='WBS Schedule'!I7 -> 46458 | J156: ='WBS Schedule'!P7 -> 105.6 | L156: ='WBS Schedule'!R7 -> 56.416 | N156: ='WBS Schedule'!S7 -> 58.62 | P156: =IF('WBS Schedule'!S7=0,1,'WBS Schedule'!R7/'WBS Schedule'!S7) -> 0.96240191 | R156: ='WBS Schedule'!J7 -> 0.56666667 | T156: ='WBS Schedule'!K7 -> 0.53424242 | V156: ='WBS Schedule'!M7 -> In Progress
A158: Demo data for illustration · Blue cells on other sheets are inputs · Change Status Date on 'Project Setup' to roll the dashboard forward

Sheet Project Setup
A1: Project Setup & Parameters
A2: Blue cells are inputs; every sheet calculates from these values
A4: Parameter | B4: Value | C4: Named range | D4: Notes
A5: Project name | B5: Vodafone–VOIS Intelligent AI Assistant
A6: Client / business unit | B6: Vodafone Intelligent Solutions (VOIS)
A7: Project code | B7: VOIS-GENAI-2026-014
A8: Project type | B8: Enterprise Generative AI · RAG · MCP integration
A9: Target platform | B9: Microsoft Azure AI Foundry (GPT-5, Foundry IQ)
A10: Azure region (demo) | B10: West Europe
A11: Delivery methodology | B11: Agile Scrum — 2-week sprints, monthly phase gates
A12: Executive sponsor | B12: Rajesh Menon — Head of Enterprise Applications
A13: Project manager | B13: Ananya Rao — PMP, PMI-ACP
A14: Product owner | B14: Vikram Desai — IT Service Excellence
A15: Project Start (Monday) | B15: 46314 | C15: ProjectStart | D15: Assumed kickoff date for the demo
A16: Status Date (data date) | B16: 46402 | C16: StatusDate | D16: Progress is reported as at this date (Week 13)
A17: Blended daily rate (₹ L / person-day) | B17: 0.32 | C17: BlendedRate | D17: Demo assumption — blended onshore/offshore rate
A18: Management reserve (% of BAC) | B18: 0.1 | C18: MgmtReserve
A19: Sprint length (calendar days) | B19: 14 | C19: SprintLen
A20: Currency / unit | B20: ₹ Lakh (1 L = ₹100,000)

Sheet WBS Schedule
A1: Vodafone–VOIS Intelligent AI Assistant — Work Breakdown Structure, Schedule & Earned Value
A2: Dates calculate from Project Start, predecessors and Holidays · Blue cells are inputs · Values in ₹ Lakh
A3: Project Start: | C3: =ProjectStart -> 46314 | D3: Status Date: | E3: =StatusDate -> 46402
A4: Gantt: black = project · grey = phase · red = activity in progress/planned · green = complete · ◆ = milestone · yellow column = status week | V4: Month 1 | Z4: Month 2 | AD4: Month 3 | AH4: Month 4 | AL4: Month 5 | AP4: +1
V5: W1 | W5: W2 | X5: W3 | Y5: W4 | Z5: W5 | AA5: W6 | AB5: W7 | AC5: W8 | AD5: W9 | AE5: W10 | AF5: W11 | AG5: W12 | AH5: W13 | AI5: W14 | AJ5: W15 | AK5: W16 | AL5: W17 | AM5: W18 | AN5: W19 | AO5: W20 | AP5: W21
A6: WBS ID | B6: Level | C6: Work Package / Activity | D6: Deliverable | E6: Responsible | F6: Predecessors | G6: Duration (work days) | H6: Start | I6: Finish | J6: Planned % | K6: Actual % | L6: Variance | M6: Status | N6: FTE | O6: Effort (person-days) | P6: Budget (BAC ₹ L) | Q6: Planned Value (PV ₹ L) | R6: Earned Value (EV ₹ L) | S6: Actual Cost (AC ₹ L) | T6: Sprint | U6: Notes / Exit Criteria | V6: =ProjectStart-WEEKDAY(ProjectStart,3)+0 -> 46314 | W6: =ProjectStart-WEEKDAY(ProjectStart,3)+7 -> 46321 | X6: =ProjectStart-WEEKDAY(ProjectStart,3)+14 -> 46328 | Y6: =ProjectStart-WEEKDAY(ProjectStart,3)+21 -> 46335 | Z6: =ProjectStart-WEEKDAY(ProjectStart,3)+28 -> 46342 | AA6: =ProjectStart-WEEKDAY(ProjectStart,3)+35 -> 46349 | AB6: =ProjectStart-WEEKDAY(ProjectStart,3)+42 -> 46356 | AC6: =ProjectStart-WEEKDAY(ProjectStart,3)+49 -> 46363 | AD6: =ProjectStart-WEEKDAY(ProjectStart,3)+56 -> 46370 | AE6: =ProjectStart-WEEKDAY(ProjectStart,3)+63 -> 46377 | AF6: =ProjectStart-WEEKDAY(ProjectStart,3)+70 -> 46384 | AG6: =ProjectStart-WEEKDAY(ProjectStart,3)+77 -> 46391 | AH6: =ProjectStart-WEEKDAY(ProjectStart,3)+84 -> 46398 | AI6: =ProjectStart-WEEKDAY(ProjectStart,3)+91 -> 46405 | AJ6: =ProjectStart-WEEKDAY(ProjectStart,3)+98 -> 46412 | AK6: =ProjectStart-WEEKDAY(ProjectStart,3)+105 -> 46419 | AL6: =ProjectStart-WEEKDAY(ProjectStart,3)+112 -> 46426 | AM6: =ProjectStart-WEEKDAY(ProjectStart,3)+119 -> 46433 | AN6: =ProjectStart-WEEKDAY(ProjectStart,3)+126 -> 46440 | AO6: =ProjectStart-WEEKDAY(ProjectStart,3)+133 -> 46447 | AP6: =ProjectStart-WEEKDAY(ProjectStart,3)+140 -> 46454
A7: 0 | B7: 0 | C7: Vodafone–VOIS Intelligent AI Assistant (Pilot) | D7: Security-reviewed, deployment-ready pilot | E7: Project Manager / Product Owner | G7: =NETWORKDAYS(H7,I7,Holidays) -> 100 | H7: =MIN(H8:H68) -> 46314 | I7: =MAX(I8:I68) -> 46458 | J7: =IF(P7=0,0,Q7/P7) -> 0.56666667 | K7: =IF(P7=0,0,R7/P7) -> 0.53424242 | L7: =K7-J7 -> -0.032424242 | M7: =IF(K7>=1,"Complete",IF(StatusDate>I7,"Overdue",IF(K7>0,IF(K7<J7-0.1,"Behind","In Progress"),IF(StatusDate>H7,"Late Start","Not Started")))) -> In Progress | O7: =O8+O20+O32+O44+O56 -> 330 | P7: =P8+P20+P32+P44+P56 -> 105.6 | Q7: =Q8+Q20+Q32+Q44+Q56 -> 59.84 | R7: =R8+R20+R32+R44+R56 -> 56.416 | S7: =S8+S20+S32+S44+S56 -> 58.62 | U7: Full enterprise rollout across all SAP/Oracle/testing apps is a subsequent phase | V7: =IF(AND($H7<=V$6+6,$I7>=V$6),1,"") -> 1 | W7: =IF(AND($H7<=W$6+6,$I7>=W$6),1,"") -> 1 | X7: =IF(AND($H7<=X$6+6,$I7>=X$6),1,"") -> 1 | Y7: =IF(AND($H7<=Y$6+6,$I7>=Y$6),1,"") -> 1 | Z7: =IF(AND($H7<=Z$6+6,$I7>=Z$6),1,"") -> 1 | AA7: =IF(AND($H7<=AA$6+6,$I7>=AA$6),1,"") -> 1 | AB7: =IF(AND($H7<=AB$6+6,$I7>=AB$6),1,"") -> 1 | AC7: =IF(AND($H7<=AC$6+6,$I7>=AC$6),1,"") -> 1 | ... AP7: =IF(AND($H7<=AP$6+6,$I7>=AP$6),1,"") -> 1
A8: 1 | B8: 1 | C8: Month 1 — Discovery, Requirements & Architecture | D8: Milestone M1: Architecture approved | E8: Project Manager | G8: =NETWORKDAYS(H8,I8,Holidays) -> 20 | H8: =MIN(H9:H19) -> 46314 | I8: =MAX(I9:I19) -> 46342 | J8: =IF(P8=0,0,Q8/P8) -> 1 | K8: =IF(P8=0,0,R8/P8) -> 1 | L8: =K8-J8 -> 0 | M8: =IF(K8>=1,"Complete",IF(StatusDate>I8,"Overdue",IF(K8>0,IF(K8<J8-0.1,"Behind","In Progress"),IF(StatusDate>H8,"Late Start","Not Started")))) -> Complete | N8: =MAX(N9:N19) -> 3 | O8: =SUM(O9:O19) -> 53 | P8: =SUM(P9:P19) -> 16.96 | Q8: =SUM(Q9:Q19) -> 16.96 | R8: =SUM(R9:R19) -> 16.96 | S8: =SUM(S9:S19) -> 16.26 | U8: Exit: Stakeholders approve the MVP scope, architecture, security approach, initial use cases and access requirements. | V8: =IF(AND($H8<=V$6+6,$I8>=V$6),1,"") -> 1 | W8: =IF(AND($H8<=W$6+6,$I8>=W$6),1,"") -> 1 | X8: =IF(AND($H8<=X$6+6,$I8>=X$6),1,"") -> 1 | Y8: =IF(AND($H8<=Y$6+6,$I8>=Y$6),1,"") -> 1 | Z8: =IF(AND($H8<=Z$6+6,$I8>=Z$6),1,"") -> 1 | AA8: =IF(AND($H8<=AA$6+6,$I8>=AA$6),1,"") | AB8: =IF(AND($H8<=AB$6+6,$I8>=AB$6),1,"") | AC8: =IF(AND($H8<=AC$6+6,$I8>=AC$6),1,"") | ... AP8: =IF(AND($H8<=AP$6+6,$I8>=AP$6),1,"")
A9: 1.1 | B9: 2 | C9: Project kickoff, objectives and stakeholder identification | D9: Project charter | E9: Project Manager | G9: 2 | H9: =WORKDAY(ProjectStart-1,1,Holidays) -> 46314 | I9: =WORKDAY(H9,G9-1,Holidays) -> 46315 | J9: =IF(StatusDate<H9,0,MIN(1,NETWORKDAYS(H9,StatusDate,Holidays)/G9)) -> 1 | K9: 1 | L9: =K9-J9 -> 0 | M9: =IF(K9>=1,"Complete",IF(StatusDate>I9,"Overdue",IF(K9>0,IF(K9<J9-0.1,"Behind","In Progress"),IF(StatusDate>H9,"Late Start","Not Started")))) -> Complete | N9: 3 | O9: =G9*N9 -> 6 | P9: =O9*BlendedRate -> 1.92 | Q9: =P9*J9 -> 1.92 | R9: =P9*K9 -> 1.92 | S9: 1.84 | T9: ="S"&(INT((H9-ProjectStart)/SprintLen)+1) -> S1 | V9: =IF(AND($H9<=V$6+6,$I9>=V$6),1,"") -> 1 | W9: =IF(AND($H9<=W$6+6,$I9>=W$6),1,"") | X9: =IF(AND($H9<=X$6+6,$I9>=X$6),1,"") | Y9: =IF(AND($H9<=Y$6+6,$I9>=Y$6),1,"") | Z9: =IF(AND($H9<=Z$6+6,$I9>=Z$6),1,"") | AA9: =IF(AND($H9<=AA$6+6,$I9>=AA$6),1,"") | AB9: =IF(AND($H9<=AB$6+6,$I9>=AB$6),1,"") | AC9: =IF(AND($H9<=AC$6+6,$I9>=AC$6),1,"") | ... AP9: =IF(AND($H9<=AP$6+6,$I9>=AP$6),1,"")
A10: 1.2 | B10: 2 | C10: Identify user personas: employees, QA, IT support, business users | D10: Persona catalogue | E10: Product Owner | F10: 1.1 | G10: 2 | H10: =WORKDAY(MAX($I$9),1,Holidays) -> 46316 | I10: =WORKDAY(H10,G10-1,Holidays) -> 46317 | J10: =IF(StatusDate<H10,0,MIN(1,NETWORKDAYS(H10,StatusDate,Holidays)/G10)) -> 1 | K10: 1 | L10: =K10-J10 -> 0 | M10: =IF(K10>=1,"Complete",IF(StatusDate>I10,"Overdue",IF(K10>0,IF(K10<J10-0.1,"Behind","In Progress"),IF(StatusDate>H10,"Late Start","Not Started")))) -> Complete | N10: 2 | O10: =G10*N10 -> 4 | P10: =O10*BlendedRate -> 1.28 | Q10: =P10*J10 -> 1.28 | R10: =P10*K10 -> 1.28 | S10: 1.23 | T10: ="S"&(INT((H10-ProjectStart)/SprintLen)+1) -> S1 | V10: =IF(AND($H10<=V$6+6,$I10>=V$6),1,"") -> 1 | W10: =IF(AND($H10<=W$6+6,$I10>=W$6),1,"") | X10: =IF(AND($H10<=X$6+6,$I10>=X$6),1,"") | Y10: =IF(AND($H10<=Y$6+6,$I10>=Y$6),1,"") | Z10: =IF(AND($H10<=Z$6+6,$I10>=Z$6),1,"") | AA10: =IF(AND($H10<=AA$6+6,$I10>=AA$6),1,"") | AB10: =IF(AND($H10<=AB$6+6,$I10>=AB$6),1,"") | AC10: =IF(AND($H10<=AC$6+6,$I10>=AC$6),1,"") | ... AP10: =IF(AND($H10<=AP$6+6,$I10>=AP$6),1,"")
A11: 1.3 | B11: 2 | C11: Gather SAP, Oracle, QA and testing use cases | D11: Use-case catalogue | E11: Product Owner / App SMEs | F11: 1.1 | G11: 3 | H11: =WORKDAY(MAX($I$9),1,Holidays) -> 46316 | I11: =WORKDAY(H11,G11-1,Holidays) -> 46318 | J11: =IF(StatusDate<H11,0,MIN(1,NETWORKDAYS(H11,StatusDate,Holidays)/G11)) -> 1 | K11: 1 | L11: =K11-J11 -> 0 | M11: =IF(K11>=1,"Complete",IF(StatusDate>I11,"Overdue",IF(K11>0,IF(K11<J11-0.1,"Behind","In Progress"),IF(StatusDate>H11,"Late Start","Not Started")))) -> Complete | N11: 3 | O11: =G11*N11 -> 9 | P11: =O11*BlendedRate -> 2.88 | Q11: =P11*J11 -> 2.88 | R11: =P11*K11 -> 2.88 | S11: 2.76 | T11: ="S"&(INT((H11-ProjectStart)/SprintLen)+1) -> S1 | V11: =IF(AND($H11<=V$6+6,$I11>=V$6),1,"") -> 1 | W11: =IF(AND($H11<=W$6+6,$I11>=W$6),1,"") | X11: =IF(AND($H11<=X$6+6,$I11>=X$6),1,"") | Y11: =IF(AND($H11<=Y$6+6,$I11>=Y$6),1,"") | Z11: =IF(AND($H11<=Z$6+6,$I11>=Z$6),1,"") | AA11: =IF(AND($H11<=AA$6+6,$I11>=AA$6),1,"") | AB11: =IF(AND($H11<=AB$6+6,$I11>=AB$6),1,"") | AC11: =IF(AND($H11<=AC$6+6,$I11>=AC$6),1,"") | ... AP11: =IF(AND($H11<=AP$6+6,$I11>=AP$6),1,"")
A12: 1.4 | B12: 2 | C12: Define functional and non-functional requirements | D12: Requirements specification | E12: Product Owner | F12: 1.3 | G12: 3 | H12: =WORKDAY(MAX($I$11),1,Holidays) -> 46321 | I12: =WORKDAY(H12,G12-1,Holidays) -> 46323 | J12: =IF(StatusDate<H12,0,MIN(1,NETWORKDAYS(H12,StatusDate,Holidays)/G12)) -> 1 | K12: 1 | L12: =K12-J12 -> 0 | M12: =IF(K12>=1,"Complete",IF(StatusDate>I12,"Overdue",IF(K12>0,IF(K12<J12-0.1,"Behind","In Progress"),IF(StatusDate>H12,"Late Start","Not Started")))) -> Complete | N12: 2 | O12: =G12*N12 -> 6 | P12: =O12*BlendedRate -> 1.92 | Q12: =P12*J12 -> 1.92 | R12: =P12*K12 -> 1.92 | S12: 1.84 | T12: ="S"&(INT((H12-ProjectStart)/SprintLen)+1) -> S1 | V12: =IF(AND($H12<=V$6+6,$I12>=V$6),1,"") | W12: =IF(AND($H12<=W$6+6,$I12>=W$6),1,"") -> 1 | X12: =IF(AND($H12<=X$6+6,$I12>=X$6),1,"") | Y12: =IF(AND($H12<=Y$6+6,$I12>=Y$6),1,"") | Z12: =IF(AND($H12<=Z$6+6,$I12>=Z$6),1,"") | AA12: =IF(AND($H12<=AA$6+6,$I12>=AA$6),1,"") | AB12: =IF(AND($H12<=AB$6+6,$I12>=AB$6),1,"") | AC12: =IF(AND($H12<=AC$6+6,$I12>=AC$6),1,"") | ... AP12: =IF(AND($H12<=AP$6+6,$I12>=AP$6),1,"")
A13: 1.5 | B13: 2 | C13: Inventory available APIs, MCP-capable tools and documentation | D13: Application inventory | E13: Backend / MCP Engineer | F13: 1.3 | G13: 3 | H13: =WORKDAY(MAX($I$11),1,Holidays) -> 46321 | I13: =WORKDAY(H13,G13-1,Holidays) -> 46323 | J13: =IF(StatusDate<H13,0,MIN(1,NETWORKDAYS(H13,StatusDate,Holidays)/G13)) -> 1 | K13: 1 | L13: =K13-J13 -> 0 | M13: =IF(K13>=1,"Complete",IF(StatusDate>I13,"Overdue",IF(K13>0,IF(K13<J13-0.1,"Behind","In Progress"),IF(StatusDate>H13,"Late Start","Not Started")))) -> Complete | N13: 2 | O13: =G13*N13 -> 6 | P13: =O13*BlendedRate -> 1.92 | Q13: =P13*J13 -> 1.92 | R13: =P13*K13 -> 1.92 | S13: 1.84 | T13: ="S"&(INT((H13-ProjectStart)/SprintLen)+1) -> S1 | V13: =IF(AND($H13<=V$6+6,$I13>=V$6),1,"") | W13: =IF(AND($H13<=W$6+6,$I13>=W$6),1,"") -> 1 | X13: =IF(AND($H13<=X$6+6,$I13>=X$6),1,"") | Y13: =IF(AND($H13<=Y$6+6,$I13>=Y$6),1,"") | Z13: =IF(AND($H13<=Z$6+6,$I13>=Z$6),1,"") | AA13: =IF(AND($H13<=AA$6+6,$I13>=AA$6),1,"") | AB13: =IF(AND($H13<=AB$6+6,$I13>=AB$6),1,"") | AC13: =IF(AND($H13<=AC$6+6,$I13>=AC$6),1,"") | ... AP13: =IF(AND($H13<=AP$6+6,$I13>=AP$6),1,"")
A14: 1.6 | B14: 2 | C14: Assess document quality, data classification and source ownership | D14: Data-source assessment | E14: AI / RAG Engineer / App SMEs | F14: 1.5 | G14: 3 | H14: =WORKDAY(MAX($I$13),1,Holidays) -> 46324 | I14: =WORKDAY(H14,G14-1,Holidays) -> 46328 | J14: =IF(StatusDate<H14,0,MIN(1,NETWORKDAYS(H14,StatusDate,Holidays)/G14)) -> 1 | K14: 1 | L14: =K14-J14 -> 0 | M14: =IF(K14>=1,"Complete",IF(StatusDate>I14,"Overdue",IF(K14>0,IF(K14<J14-0.1,"Behind","In Progress"),IF(StatusDate>H14,"Late Start","Not Started")))) -> Complete | N14: 2 | O14: =G14*N14 -> 6 | P14: =O14*BlendedRate -> 1.92 | Q14: =P14*J14 -> 1.92 | R14: =P14*K14 -> 1.92 | S14: 1.84 | T14: ="S"&(INT((H14-ProjectStart)/SprintLen)+1) -> S1 | V14: =IF(AND($H14<=V$6+6,$I14>=V$6),1,"") | W14: =IF(AND($H14<=W$6+6,$I14>=W$6),1,"") -> 1 | X14: =IF(AND($H14<=X$6+6,$I14>=X$6),1,"") -> 1 | Y14: =IF(AND($H14<=Y$6+6,$I14>=Y$6),1,"") | Z14: =IF(AND($H14<=Z$6+6,$I14>=Z$6),1,"") | AA14: =IF(AND($H14<=AA$6+6,$I14>=AA$6),1,"") | AB14: =IF(AND($H14<=AB$6+6,$I14>=AB$6),1,"") | AC14: =IF(AND($H14<=AC$6+6,$I14>=AC$6),1,"") | ... AP14: =IF(AND($H14<=AP$6+6,$I14>=AP$6),1,"")
A15: 1.7 | B15: 2 | C15: Design Azure AI Foundry and application architecture | D15: Architecture diagram | E15: Solution Architect | F15: 1.4 | G15: 3 | H15: =WORKDAY(MAX($I$12),1,Holidays) -> 46324 | I15: =WORKDAY(H15,G15-1,Holidays) -> 46328 | J15: =IF(StatusDate<H15,0,MIN(1,NETWORKDAYS(H15,StatusDate,Holidays)/G15)) -> 1 | K15: 1 | L15: =K15-J15 -> 0 | M15: =IF(K15>=1,"Complete",IF(StatusDate>I15,"Overdue",IF(K15>0,IF(K15<J15-0.1,"Behind","In Progress"),IF(StatusDate>H15,"Late Start","Not Started")))) -> Complete | N15: 2 | O15: =G15*N15 -> 6 | P15: =O15*BlendedRate -> 1.92 | Q15: =P15*J15 -> 1.92 | R15: =P15*K15 -> 1.92 | S15: 1.84 | T15: ="S"&(INT((H15-ProjectStart)/SprintLen)+1) -> S1 | V15: =IF(AND($H15<=V$6+6,$I15>=V$6),1,"") | W15: =IF(AND($H15<=W$6+6,$I15>=W$6),1,"") -> 1 | X15: =IF(AND($H15<=X$6+6,$I15>=X$6),1,"") -> 1 | Y15: =IF(AND($H15<=Y$6+6,$I15>=Y$6),1,"") | Z15: =IF(AND($H15<=Z$6+6,$I15>=Z$6),1,"") | AA15: =IF(AND($H15<=AA$6+6,$I15>=AA$6),1,"") | AB15: =IF(AND($H15<=AB$6+6,$I15>=AB$6),1,"") | AC15: =IF(AND($H15<=AC$6+6,$I15>=AC$6),1,"") | ... AP15: =IF(AND($H15<=AP$6+6,$I15>=AP$6),1,"")
A16: 1.8 | B16: 2 | C16: Define RAG, Foundry IQ and MCP interaction patterns | D16: Integration design | E16: Solution Architect | F16: 1.7, 1.6 | G16: 2 | H16: =WORKDAY(MAX($I$15,$I$14),1,Holidays) -> 46329 | I16: =WORKDAY(H16,G16-1,Holidays) -> 46330 | J16: =IF(StatusDate<H16,0,MIN(1,NETWORKDAYS(H16,StatusDate,Holidays)/G16)) -> 1 | K16: 1 | L16: =K16-J16 -> 0 | M16: =IF(K16>=1,"Complete",IF(StatusDate>I16,"Overdue",IF(K16>0,IF(K16<J16-0.1,"Behind","In Progress"),IF(StatusDate>H16,"Late Start","Not Started")))) -> Complete | N16: 2 | O16: =G16*N16 -> 4 | P16: =O16*BlendedRate -> 1.28 | Q16: =P16*J16 -> 1.28 | R16: =P16*K16 -> 1.28 | S16: 1.23 | T16: ="S"&(INT((H16-ProjectStart)/SprintLen)+1) -> S2 | V16: =IF(AND($H16<=V$6+6,$I16>=V$6),1,"") | W16: =IF(AND($H16<=W$6+6,$I16>=W$6),1,"") | X16: =IF(AND($H16<=X$6+6,$I16>=X$6),1,"") -> 1 | Y16: =IF(AND($H16<=Y$6+6,$I16>=Y$6),1,"") | Z16: =IF(AND($H16<=Z$6+6,$I16>=Z$6),1,"") | AA16: =IF(AND($H16<=AA$6+6,$I16>=AA$6),1,"") | AB16: =IF(AND($H16<=AB$6+6,$I16>=AB$6),1,"") | AC16: =IF(AND($H16<=AC$6+6,$I16>=AC$6),1,"") | ... AP16: =IF(AND($H16<=AP$6+6,$I16>=AP$6),1,"")
A17: 1.9 | B17: 2 | C17: Design identity, access, network and secrets management | D17: Security design | E17: Security Engineer | F17: 1.7 | G17: 2 | H17: =WORKDAY(MAX($I$15),1,Holidays) -> 46329 | I17: =WORKDAY(H17,G17-1,Holidays) -> 46330 | J17: =IF(StatusDate<H17,0,MIN(1,NETWORKDAYS(H17,StatusDate,Holidays)/G17)) -> 1 | K17: 1 | L17: =K17-J17 -> 0 | M17: =IF(K17>=1,"Complete",IF(StatusDate>I17,"Overdue",IF(K17>0,IF(K17<J17-0.1,"Behind","In Progress"),IF(StatusDate>H17,"Late Start","Not Started")))) -> Complete | N17: 1 | O17: =G17*N17 -> 2 | P17: =O17*BlendedRate -> 0.64 | Q17: =P17*J17 -> 0.64 | R17: =P17*K17 -> 0.64 | S17: 0.61 | T17: ="S"&(INT((H17-ProjectStart)/SprintLen)+1) -> S2 | V17: =IF(AND($H17<=V$6+6,$I17>=V$6),1,"") | W17: =IF(AND($H17<=W$6+6,$I17>=W$6),1,"") | X17: =IF(AND($H17<=X$6+6,$I17>=X$6),1,"") -> 1 | Y17: =IF(AND($H17<=Y$6+6,$I17>=Y$6),1,"") | Z17: =IF(AND($H17<=Z$6+6,$I17>=Z$6),1,"") | AA17: =IF(AND($H17<=AA$6+6,$I17>=AA$6),1,"") | AB17: =IF(AND($H17<=AB$6+6,$I17>=AB$6),1,"") | AC17: =IF(AND($H17<=AC$6+6,$I17>=AC$6),1,"") | ... AP17: =IF(AND($H17<=AP$6+6,$I17>=AP$6),1,"")
A18: 1.10 | B18: 2 | C18: Create backlog, sprint plan, risks and acceptance criteria | D18: Delivery plan | E18: Project Manager | F18: 1.8, 1.9 | G18: 2 | H18: =WORKDAY(MAX($I$16,$I$17),1,Holidays) -> 46331 | I18: =WORKDAY(H18,G18-1,Holidays) -> 46332 | J18: =IF(StatusDate<H18,0,MIN(1,NETWORKDAYS(H18,StatusDate,Holidays)/G18)) -> 1 | K18: 1 | L18: =K18-J18 -> 0 | M18: =IF(K18>=1,"Complete",IF(StatusDate>I18,"Overdue",IF(K18>0,IF(K18<J18-0.1,"Behind","In Progress"),IF(StatusDate>H18,"Late Start","Not Started")))) -> Complete | N18: 2 | O18: =G18*N18 -> 4 | P18: =O18*BlendedRate -> 1.28 | Q18: =P18*J18 -> 1.28 | R18: =P18*K18 -> 1.28 | S18: 1.23 | T18: ="S"&(INT((H18-ProjectStart)/SprintLen)+1) -> S2 | V18: =IF(AND($H18<=V$6+6,$I18>=V$6),1,"") | W18: =IF(AND($H18<=W$6+6,$I18>=W$6),1,"") | X18: =IF(AND($H18<=X$6+6,$I18>=X$6),1,"") -> 1 | Y18: =IF(AND($H18<=Y$6+6,$I18>=Y$6),1,"") | Z18: =IF(AND($H18<=Z$6+6,$I18>=Z$6),1,"") | AA18: =IF(AND($H18<=AA$6+6,$I18>=AA$6),1,"") | AB18: =IF(AND($H18<=AB$6+6,$I18>=AB$6),1,"") | AC18: =IF(AND($H18<=AC$6+6,$I18>=AC$6),1,"") | ... AP18: =IF(AND($H18<=AP$6+6,$I18>=AP$6),1,"")
A19: M1 | B19: 2 | C19: ◆ Milestone M1 — Architecture approved | D19: Signed-off requirements and design | E19: Project Manager / Sponsor | F19: End of Week 4 | G19: 0 | H19: =I19 -> 46342 | I19: =WORKDAY(ProjectStart-1,20,Holidays) -> 46342 | J19: =IF(StatusDate>=I19,1,0) -> 1 | K19: 1 | L19: =K19-J19 -> 0 | M19: =IF(K19>=1,"Complete",IF(StatusDate>I19,"Overdue",IF(K19>0,IF(K19<J19-0.1,"Behind","In Progress"),IF(StatusDate>H19,"Late Start","Not Started")))) -> Complete | T19: ="S"&(INT((H19-ProjectStart)/SprintLen)+1) -> S3 | U19: Gate: all phase deliverables complete before sign-off | V19: =IF(AND($I19>=V$6,$I19<=V$6+6),"◆","") | W19: =IF(AND($I19>=W$6,$I19<=W$6+6),"◆","") | X19: =IF(AND($I19>=X$6,$I19<=X$6+6),"◆","") | Y19: =IF(AND($I19>=Y$6,$I19<=Y$6+6),"◆","") | Z19: =IF(AND($I19>=Z$6,$I19<=Z$6+6),"◆","") -> ◆ | AA19: =IF(AND($I19>=AA$6,$I19<=AA$6+6),"◆","") | AB19: =IF(AND($I19>=AB$6,$I19<=AB$6+6),"◆","") | AC19: =IF(AND($I19>=AC$6,$I19<=AC$6+6),"◆","") | ... AP19: =IF(AND($I19>=AP$6,$I19<=AP$6+6),"◆","")
A20: 2 | B20: 1 | C20: Month 2 — AI Foundation & Knowledge Retrieval | D20: Milestone M2: AI assistant MVP | E20: Project Manager | G20: =NETWORKDAYS(H20,I20,Holidays) -> 20 | H20: =MIN(H21:H31) -> 46343 | I20: =MAX(I21:I31) -> 46371 | J20: =IF(P20=0,0,Q20/P20) -> 1 | K20: =IF(P20=0,0,R20/P20) -> 1 | L20: =K20-J20 -> 0 | M20: =IF(K20>=1,"Complete",IF(StatusDate>I20,"Overdue",IF(K20>0,IF(K20<J20-0.1,"Behind","In Progress"),IF(StatusDate>H20,"Late Start","Not Started")))) -> Complete | N20: =MAX(N21:N31) -> 3 | O20: =SUM(O21:O31) -> 54 | P20: =SUM(P21:P31) -> 17.28 | Q20: =SUM(Q21:Q31) -> 17.28 | R20: =SUM(R21:R31) -> 17.28 | S20: =SUM(S21:S31) -> 17.9 | U20: Exit: A user can ask questions about approved sample documentation and receive relevant, source-grounded answers through the chat interface. | V20: =IF(AND($H20<=V$6+6,$I20>=V$6),1,"") | W20: =IF(AND($H20<=W$6+6,$I20>=W$6),1,"") | X20: =IF(AND($H20<=X$6+6,$I20>=X$6),1,"") | Y20: =IF(AND($H20<=Y$6+6,$I20>=Y$6),1,"") | Z20: =IF(AND($H20<=Z$6+6,$I20>=Z$6),1,"") -> 1 | AA20: =IF(AND($H20<=AA$6+6,$I20>=AA$6),1,"") -> 1 | AB20: =IF(AND($H20<=AB$6+6,$I20>=AB$6),1,"") -> 1 | AC20: =IF(AND($H20<=AC$6+6,$I20>=AC$6),1,"") -> 1 | ... AP20: =IF(AND($H20<=AP$6+6,$I20>=AP$6),1,"")
A21: 2.1 | B21: 2 | C21: Provision approved Azure development resources | D21: Development environment | E21: DevOps Engineer | F21: M1 | G21: 2 | H21: =WORKDAY(MAX($I$19),1,Holidays) -> 46343 | I21: =WORKDAY(H21,G21-1,Holidays) -> 46344 | J21: =IF(StatusDate<H21,0,MIN(1,NETWORKDAYS(H21,StatusDate,Holidays)/G21)) -> 1 | K21: 1 | L21: =K21-J21 -> 0 | M21: =IF(K21>=1,"Complete",IF(StatusDate>I21,"Overdue",IF(K21>0,IF(K21<J21-0.1,"Behind","In Progress"),IF(StatusDate>H21,"Late Start","Not Started")))) -> Complete | N21: 1 | O21: =G21*N21 -> 2 | P21: =O21*BlendedRate -> 0.64 | Q21: =P21*J21 -> 0.64 | R21: =P21*K21 -> 0.64 | S21: 0.65 | T21: ="S"&(INT((H21-ProjectStart)/SprintLen)+1) -> S3 | V21: =IF(AND($H21<=V$6+6,$I21>=V$6),1,"") | W21: =IF(AND($H21<=W$6+6,$I21>=W$6),1,"") | X21: =IF(AND($H21<=X$6+6,$I21>=X$6),1,"") | Y21: =IF(AND($H21<=Y$6+6,$I21>=Y$6),1,"") | Z21: =IF(AND($H21<=Z$6+6,$I21>=Z$6),1,"") -> 1 | AA21: =IF(AND($H21<=AA$6+6,$I21>=AA$6),1,"") | AB21: =IF(AND($H21<=AB$6+6,$I21>=AB$6),1,"") | AC21: =IF(AND($H21<=AC$6+6,$I21>=AC$6),1,"") | ... AP21: =IF(AND($H21<=AP$6+6,$I21>=AP$6),1,"")
A22: 2.2 | B22: 2 | C22: Configure AI Foundry project and model access | D22: Foundry environment | E22: AI / RAG Engineer | F22: 2.1 | G22: 2 | H22: =WORKDAY(MAX($I$21),1,Holidays) -> 46345 | I22: =WORKDAY(H22,G22-1,Holidays) -> 46346 | J22: =IF(StatusDate<H22,0,MIN(1,NETWORKDAYS(H22,StatusDate,Holidays)/G22)) -> 1 | K22: 1 | L22: =K22-J22 -> 0 | M22: =IF(K22>=1,"Complete",IF(StatusDate>I22,"Overdue",IF(K22>0,IF(K22<J22-0.1,"Behind","In Progress"),IF(StatusDate>H22,"Late Start","Not Started")))) -> Complete | N22: 2 | O22: =G22*N22 -> 4 | P22: =O22*BlendedRate -> 1.28 | Q22: =P22*J22 -> 1.28 | R22: =P22*K22 -> 1.28 | S22: 1.31 | T22: ="S"&(INT((H22-ProjectStart)/SprintLen)+1) -> S3 | V22: =IF(AND($H22<=V$6+6,$I22>=V$6),1,"") | W22: =IF(AND($H22<=W$6+6,$I22>=W$6),1,"") | X22: =IF(AND($H22<=X$6+6,$I22>=X$6),1,"") | Y22: =IF(AND($H22<=Y$6+6,$I22>=Y$6),1,"") | Z22: =IF(AND($H22<=Z$6+6,$I22>=Z$6),1,"") -> 1 | AA22: =IF(AND($H22<=AA$6+6,$I22>=AA$6),1,"") | AB22: =IF(AND($H22<=AB$6+6,$I22>=AB$6),1,"") | AC22: =IF(AND($H22<=AC$6+6,$I22>=AC$6),1,"") | ... AP22: =IF(AND($H22<=AP$6+6,$I22>=AP$6),1,"")
A23: 2.3 | B23: 2 | C23: Validate GPT-5 availability, deployment and inference | D23: Model integration | E23: AI / RAG Engineer | F23: 2.2 | G23: 2 | H23: =WORKDAY(MAX($I$22),1,Holidays) -> 46349 | I23: =WORKDAY(H23,G23-1,Holidays) -> 46351 | J23: =IF(StatusDate<H23,0,MIN(1,NETWORKDAYS(H23,StatusDate,Holidays)/G23)) -> 1 | K23: 1 | L23: =K23-J23 -> 0 | M23: =IF(K23>=1,"Complete",IF(StatusDate>I23,"Overdue",IF(K23>0,IF(K23<J23-0.1,"Behind","In Progress"),IF(StatusDate>H23,"Late Start","Not Started")))) -> Complete | N23: 2 | O23: =G23*N23 -> 4 | P23: =O23*BlendedRate -> 1.28 | Q23: =P23*J23 -> 1.28 | R23: =P23*K23 -> 1.28 | S23: 1.31 | T23: ="S"&(INT((H23-ProjectStart)/SprintLen)+1) -> S3 | V23: =IF(AND($H23<=V$6+6,$I23>=V$6),1,"") | W23: =IF(AND($H23<=W$6+6,$I23>=W$6),1,"") | X23: =IF(AND($H23<=X$6+6,$I23>=X$6),1,"") | Y23: =IF(AND($H23<=Y$6+6,$I23>=Y$6),1,"") | Z23: =IF(AND($H23<=Z$6+6,$I23>=Z$6),1,"") | AA23: =IF(AND($H23<=AA$6+6,$I23>=AA$6),1,"") -> 1 | AB23: =IF(AND($H23<=AB$6+6,$I23>=AB$6),1,"") | AC23: =IF(AND($H23<=AC$6+6,$I23>=AC$6),1,"") | ... AP23: =IF(AND($H23<=AP$6+6,$I23>=AP$6),1,"")
A24: 2.4 | B24: 2 | C24: Evaluate GPT_Image-2 availability and visual-generation use cases | D24: Image capability proof of concept | E24: AI / RAG Engineer | F24: 2.3 | G24: 1 | H24: =WORKDAY(MAX($I$23),1,Holidays) -> 46352 | I24: =WORKDAY(H24,G24-1,Holidays) -> 46352 | J24: =IF(StatusDate<H24,0,MIN(1,NETWORKDAYS(H24,StatusDate,Holidays)/G24)) -> 1 | K24: 1 | L24: =K24-J24 -> 0 | M24: =IF(K24>=1,"Complete",IF(StatusDate>I24,"Overdue",IF(K24>0,IF(K24<J24-0.1,"Behind","In Progress"),IF(StatusDate>H24,"Late Start","Not Started")))) -> Complete | N24: 1 | O24: =G24*N24 -> 1 | P24: =O24*BlendedRate -> 0.32 | Q24: =P24*J24 -> 0.32 | R24: =P24*K24 -> 0.32 | S24: 0.33 | T24: ="S"&(INT((H24-ProjectStart)/SprintLen)+1) -> S3 | V24: =IF(AND($H24<=V$6+6,$I24>=V$6),1,"") | W24: =IF(AND($H24<=W$6+6,$I24>=W$6),1,"") | X24: =IF(AND($H24<=X$6+6,$I24>=X$6),1,"") | Y24: =IF(AND($H24<=Y$6+6,$I24>=Y$6),1,"") | Z24: =IF(AND($H24<=Z$6+6,$I24>=Z$6),1,"") | AA24: =IF(AND($H24<=AA$6+6,$I24>=AA$6),1,"") -> 1 | AB24: =IF(AND($H24<=AB$6+6,$I24>=AB$6),1,"") | AC24: =IF(AND($H24<=AC$6+6,$I24>=AC$6),1,"") | ... AP24: =IF(AND($H24<=AP$6+6,$I24>=AP$6),1,"")
A25: 2.5 | B25: 2 | C25: Prepare sample SAP, Oracle, QA and testing documents | D25: Curated test corpus | E25: App SMEs / AI / RAG Engineer | F25: M1 | G25: 3 | H25: =WORKDAY(MAX($I$19),1,Holidays) -> 46343 | I25: =WORKDAY(H25,G25-1,Holidays) -> 46345 | J25: =IF(StatusDate<H25,0,MIN(1,NETWORKDAYS(H25,StatusDate,Holidays)/G25)) -> 1 | K25: 1 | L25: =K25-J25 -> 0 | M25: =IF(K25>=1,"Complete",IF(StatusDate>I25,"Overdue",IF(K25>0,IF(K25<J25-0.1,"Behind","In Progress"),IF(StatusDate>H25,"Late Start","Not Started")))) -> Complete | N25: 3 | O25: =G25*N25 -> 9 | P25: =O25*BlendedRate -> 2.88 | Q25: =P25*J25 -> 2.88 | R25: =P25*K25 -> 2.88 | S25: 2.94 | T25: ="S"&(INT((H25-ProjectStart)/SprintLen)+1) -> S3 | V25: =IF(AND($H25<=V$6+6,$I25>=V$6),1,"") | W25: =IF(AND($H25<=W$6+6,$I25>=W$6),1,"") | X25: =IF(AND($H25<=X$6+6,$I25>=X$6),1,"") | Y25: =IF(AND($H25<=Y$6+6,$I25>=Y$6),1,"") | Z25: =IF(AND($H25<=Z$6+6,$I25>=Z$6),1,"") -> 1 | AA25: =IF(AND($H25<=AA$6+6,$I25>=AA$6),1,"") | AB25: =IF(AND($H25<=AB$6+6,$I25>=AB$6),1,"") | AC25: =IF(AND($H25<=AC$6+6,$I25>=AC$6),1,"") | ... AP25: =IF(AND($H25<=AP$6+6,$I25>=AP$6),1,"")
A26: 2.6 | B26: 2 | C26: Configure Foundry IQ knowledge sources and retrieval | D26: Knowledge retrieval pipeline | E26: AI / RAG Engineer | F26: 2.3, 2.5 | G26: 4 | H26: =WORKDAY(MAX($I$23,$I$25),1,Holidays) -> 46352 | I26: =WORKDAY(H26,G26-1,Holidays) -> 46357 | J26: =IF(StatusDate<H26,0,MIN(1,NETWORKDAYS(H26,StatusDate,Holidays)/G26)) -> 1 | K26: 1 | L26: =K26-J26 -> 0 | M26: =IF(K26>=1,"Complete",IF(StatusDate>I26,"Overdue",IF(K26>0,IF(K26<J26-0.1,"Behind","In Progress"),IF(StatusDate>H26,"Late Start","Not Started")))) -> Complete | N26: 2 | O26: =G26*N26 -> 8 | P26: =O26*BlendedRate -> 2.56 | Q26: =P26*J26 -> 2.56 | R26: =P26*K26 -> 2.56 | S26: 2.87 | T26: ="S"&(INT((H26-ProjectStart)/SprintLen)+1) -> S3 | V26: =IF(AND($H26<=V$6+6,$I26>=V$6),1,"") | W26: =IF(AND($H26<=W$6+6,$I26>=W$6),1,"") | X26: =IF(AND($H26<=X$6+6,$I26>=X$6),1,"") | Y26: =IF(AND($H26<=Y$6+6,$I26>=Y$6),1,"") | Z26: =IF(AND($H26<=Z$6+6,$I26>=Z$6),1,"") | AA26: =IF(AND($H26<=AA$6+6,$I26>=AA$6),1,"") -> 1 | AB26: =IF(AND($H26<=AB$6+6,$I26>=AB$6),1,"") -> 1 | AC26: =IF(AND($H26<=AC$6+6,$I26>=AC$6),1,"") | ... AP26: =IF(AND($H26<=AP$6+6,$I26>=AP$6),1,"")
A27: 2.7 | B27: 2 | C27: Implement chunking, indexing and metadata strategy | D27: Searchable knowledge base | E27: AI / RAG Engineer | F27: 2.6 | G27: 3 | H27: =WORKDAY(MAX($I$26),1,Holidays) -> 46358 | I27: =WORKDAY(H27,G27-1,Holidays) -> 46360 | J27: =IF(StatusDate<H27,0,MIN(1,NETWORKDAYS(H27,StatusDate,Holidays)/G27)) -> 1 | K27: 1 | L27: =K27-J27 -> 0 | M27: =IF(K27>=1,"Complete",IF(StatusDate>I27,"Overdue",IF(K27>0,IF(K27<J27-0.1,"Behind","In Progress"),IF(StatusDate>H27,"Late Start","Not Started")))) -> Complete | N27: 2 | O27: =G27*N27 -> 6 | P27: =O27*BlendedRate -> 1.92 | Q27: =P27*J27 -> 1.92 | R27: =P27*K27 -> 1.92 | S27: 1.96 | T27: ="S"&(INT((H27-ProjectStart)/SprintLen)+1) -> S4 | V27: =IF(AND($H27<=V$6+6,$I27>=V$6),1,"") | W27: =IF(AND($H27<=W$6+6,$I27>=W$6),1,"") | X27: =IF(AND($H27<=X$6+6,$I27>=X$6),1,"") | Y27: =IF(AND($H27<=Y$6+6,$I27>=Y$6),1,"") | Z27: =IF(AND($H27<=Z$6+6,$I27>=Z$6),1,"") | AA27: =IF(AND($H27<=AA$6+6,$I27>=AA$6),1,"") | AB27: =IF(AND($H27<=AB$6+6,$I27>=AB$6),1,"") -> 1 | AC27: =IF(AND($H27<=AC$6+6,$I27>=AC$6),1,"") | ... AP27: =IF(AND($H27<=AP$6+6,$I27>=AP$6),1,"")
A28: 2.8 | B28: 2 | C28: Implement grounded answers, citations and source references | D28: RAG response workflow | E28: AI / RAG Engineer | F28: 2.7 | G28: 3 | H28: =WORKDAY(MAX($I$27),1,Holidays) -> 46363 | I28: =WORKDAY(H28,G28-1,Holidays) -> 46365 | J28: =IF(StatusDate<H28,0,MIN(1,NETWORKDAYS(H28,StatusDate,Holidays)/G28)) -> 1 | K28: 1 | L28: =K28-J28 -> 0 | M28: =IF(K28>=1,"Complete",IF(StatusDate>I28,"Overdue",IF(K28>0,IF(K28<J28-0.1,"Behind","In Progress"),IF(StatusDate>H28,"Late Start","Not Started")))) -> Complete | N28: 2 | O28: =G28*N28 -> 6 | P28: =O28*BlendedRate -> 1.92 | Q28: =P28*J28 -> 1.92 | R28: =P28*K28 -> 1.92 | S28: 1.96 | T28: ="S"&(INT((H28-ProjectStart)/SprintLen)+1) -> S4 | V28: =IF(AND($H28<=V$6+6,$I28>=V$6),1,"") | W28: =IF(AND($H28<=W$6+6,$I28>=W$6),1,"") | X28: =IF(AND($H28<=X$6+6,$I28>=X$6),1,"") | Y28: =IF(AND($H28<=Y$6+6,$I28>=Y$6),1,"") | Z28: =IF(AND($H28<=Z$6+6,$I28>=Z$6),1,"") | AA28: =IF(AND($H28<=AA$6+6,$I28>=AA$6),1,"") | AB28: =IF(AND($H28<=AB$6+6,$I28>=AB$6),1,"") | AC28: =IF(AND($H28<=AC$6+6,$I28>=AC$6),1,"") -> 1 | ... AP28: =IF(AND($H28<=AP$6+6,$I28>=AP$6),1,"")
A29: 2.9 | B29: 2 | C29: Build chat UI, conversation flow and application navigation | D29: Web chat prototype | E29: Frontend Engineer | F29: 2.3 | G29: 4 | H29: =WORKDAY(MAX($I$23),1,Holidays) -> 46352 | I29: =WORKDAY(H29,G29-1,Holidays) -> 46357 | J29: =IF(StatusDate<H29,0,MIN(1,NETWORKDAYS(H29,StatusDate,Holidays)/G29)) -> 1 | K29: 1 | L29: =K29-J29 -> 0 | M29: =IF(K29>=1,"Complete",IF(StatusDate>I29,"Overdue",IF(K29>0,IF(K29<J29-0.1,"Behind","In Progress"),IF(StatusDate>H29,"Late Start","Not Started")))) -> Complete | N29: 2 | O29: =G29*N29 -> 8 | P29: =O29*BlendedRate -> 2.56 | Q29: =P29*J29 -> 2.56 | R29: =P29*K29 -> 2.56 | S29: 2.61 | T29: ="S"&(INT((H29-ProjectStart)/SprintLen)+1) -> S3 | V29: =IF(AND($H29<=V$6+6,$I29>=V$6),1,"") | W29: =IF(AND($H29<=W$6+6,$I29>=W$6),1,"") | X29: =IF(AND($H29<=X$6+6,$I29>=X$6),1,"") | Y29: =IF(AND($H29<=Y$6+6,$I29>=Y$6),1,"") | Z29: =IF(AND($H29<=Z$6+6,$I29>=Z$6),1,"") | AA29: =IF(AND($H29<=AA$6+6,$I29>=AA$6),1,"") -> 1 | AB29: =IF(AND($H29<=AB$6+6,$I29>=AB$6),1,"") -> 1 | AC29: =IF(AND($H29<=AC$6+6,$I29>=AC$6),1,"") | ... AP29: =IF(AND($H29<=AP$6+6,$I29>=AP$6),1,"")
A30: 2.10 | B30: 2 | C30: Add logging, error handling and baseline evaluation | D30: Baseline evaluation report | E30: QA Engineer / AI / RAG Engineer | F30: 2.8, 2.9 | G30: 3 | H30: =WORKDAY(MAX($I$28,$I$29),1,Holidays) -> 46366 | I30: =WORKDAY(H30,G30-1,Holidays) -> 46370 | J30: =IF(StatusDate<H30,0,MIN(1,NETWORKDAYS(H30,StatusDate,Holidays)/G30)) -> 1 | K30: 1 | L30: =K30-J30 -> 0 | M30: =IF(K30>=1,"Complete",IF(StatusDate>I30,"Overdue",IF(K30>0,IF(K30<J30-0.1,"Behind","In Progress"),IF(StatusDate>H30,"Late Start","Not Started")))) -> Complete | N30: 2 | O30: =G30*N30 -> 6 | P30: =O30*BlendedRate -> 1.92 | Q30: =P30*J30 -> 1.92 | R30: =P30*K30 -> 1.92 | S30: 1.96 | T30: ="S"&(INT((H30-ProjectStart)/SprintLen)+1) -> S4 | V30: =IF(AND($H30<=V$6+6,$I30>=V$6),1,"") | W30: =IF(AND($H30<=W$6+6,$I30>=W$6),1,"") | X30: =IF(AND($H30<=X$6+6,$I30>=X$6),1,"") | Y30: =IF(AND($H30<=Y$6+6,$I30>=Y$6),1,"") | Z30: =IF(AND($H30<=Z$6+6,$I30>=Z$6),1,"") | AA30: =IF(AND($H30<=AA$6+6,$I30>=AA$6),1,"") | AB30: =IF(AND($H30<=AB$6+6,$I30>=AB$6),1,"") | AC30: =IF(AND($H30<=AC$6+6,$I30>=AC$6),1,"") -> 1 | ... AP30: =IF(AND($H30<=AP$6+6,$I30>=AP$6),1,"")
A31: M2 | B31: 2 | C31: ◆ Milestone M2 — AI assistant MVP | D31: Grounded answers from approved documents | E31: Project Manager / Sponsor | F31: End of Week 8 | G31: 0 | H31: =I31 -> 46371 | I31: =WORKDAY(ProjectStart-1,40,Holidays) -> 46371 | J31: =IF(StatusDate>=I31,1,0) -> 1 | K31: 1 | L31: =K31-J31 -> 0 | M31: =IF(K31>=1,"Complete",IF(StatusDate>I31,"Overdue",IF(K31>0,IF(K31<J31-0.1,"Behind","In Progress"),IF(StatusDate>H31,"Late Start","Not Started")))) -> Complete | T31: ="S"&(INT((H31-ProjectStart)/SprintLen)+1) -> S5 | U31: Gate: all phase deliverables complete before sign-off | V31: =IF(AND($I31>=V$6,$I31<=V$6+6),"◆","") | W31: =IF(AND($I31>=W$6,$I31<=W$6+6),"◆","") | X31: =IF(AND($I31>=X$6,$I31<=X$6+6),"◆","") | Y31: =IF(AND($I31>=Y$6,$I31<=Y$6+6),"◆","") | Z31: =IF(AND($I31>=Z$6,$I31<=Z$6+6),"◆","") | AA31: =IF(AND($I31>=AA$6,$I31<=AA$6+6),"◆","") | AB31: =IF(AND($I31>=AB$6,$I31<=AB$6+6),"◆","") | AC31: =IF(AND($I31>=AC$6,$I31<=AC$6+6),"◆","") | ... AP31: =IF(AND($I31>=AP$6,$I31<=AP$6+6),"◆","")
A32: 3 | B32: 1 | C32: Month 3 — MCP & Enterprise Integration | D32: Milestone M3: Application integrations | E32: Project Manager | G32: =NETWORKDAYS(H32,I32,Holidays) -> 20 | H32: =MIN(H33:H43) -> 46372 | I32: =MAX(I33:I43) -> 46401 | J32: =IF(P32=0,0,Q32/P32) -> 1 | K32: =IF(P32=0,0,R32/P32) -> 0.84459459 | L32: =K32-J32 -> -0.15540541 | M32: =IF(K32>=1,"Complete",IF(StatusDate>I32,"Overdue",IF(K32>0,IF(K32<J32-0.1,"Behind","In Progress"),IF(StatusDate>H32,"Late Start","Not Started")))) -> Overdue | N32: =MAX(N33:N43) -> 3 | O32: =SUM(O33:O43) -> 74 | P32: =SUM(P33:P43) -> 23.68 | Q32: =SUM(Q33:Q43) -> 23.68 | R32: =SUM(R33:R43) -> 20 | S32: =SUM(S33:S43) -> 22.28 | U32: Exit: The assistant answers knowledge questions and executes approved, read-only operations against available test integrations (SAP/Oracle scope subject to API access, licensing and environment readiness). | V32: =IF(AND($H32<=V$6+6,$I32>=V$6),1,"") | W32: =IF(AND($H32<=W$6+6,$I32>=W$6),1,"") | X32: =IF(AND($H32<=X$6+6,$I32>=X$6),1,"") | Y32: =IF(AND($H32<=Y$6+6,$I32>=Y$6),1,"") | Z32: =IF(AND($H32<=Z$6+6,$I32>=Z$6),1,"") | AA32: =IF(AND($H32<=AA$6+6,$I32>=AA$6),1,"") | AB32: =IF(AND($H32<=AB$6+6,$I32>=AB$6),1,"") | AC32: =IF(AND($H32<=AC$6+6,$I32>=AC$6),1,"") | ... AP32: =IF(AND($H32<=AP$6+6,$I32>=AP$6),1,"")
A33: 3.1 | B33: 2 | C33: Define MCP server/client architecture and tool contracts | D33: MCP design specification | E33: Backend / MCP Engineer | F33: M2 | G33: 3 | H33: =WORKDAY(MAX($I$31),1,Holidays) -> 46372 | I33: =WORKDAY(H33,G33-1,Holidays) -> 46374 | J33: =IF(StatusDate<H33,0,MIN(1,NETWORKDAYS(H33,StatusDate,Holidays)/G33)) -> 1 | K33: 1 | L33: =K33-J33 -> 0 | M33: =IF(K33>=1,"Complete",IF(StatusDate>I33,"Overdue",IF(K33>0,IF(K33<J33-0.1,"Behind","In Progress"),IF(StatusDate>H33,"Late Start","Not Started")))) -> Complete | N33: 2 | O33: =G33*N33 -> 6 | P33: =O33*BlendedRate -> 1.92 | Q33: =P33*J33 -> 1.92 | R33: =P33*K33 -> 1.92 | S33: 2 | T33: ="S"&(INT((H33-ProjectStart)/SprintLen)+1) -> S5 | V33: =IF(AND($H33<=V$6+6,$I33>=V$6),1,"") | W33: =IF(AND($H33<=W$6+6,$I33>=W$6),1,"") | X33: =IF(AND($H33<=X$6+6,$I33>=X$6),1,"") | Y33: =IF(AND($H33<=Y$6+6,$I33>=Y$6),1,"") | Z33: =IF(AND($H33<=Z$6+6,$I33>=Z$6),1,"") | AA33: =IF(AND($H33<=AA$6+6,$I33>=AA$6),1,"") | AB33: =IF(AND($H33<=AB$6+6,$I33>=AB$6),1,"") | AC33: =IF(AND($H33<=AC$6+6,$I33>=AC$6),1,"") | ... AP33: =IF(AND($H33<=AP$6+6,$I33>=AP$6),1,"")
A34: 3.2 | B34: 2 | C34: Implement MCP connection and authentication | D34: Working MCP connection | E34: Backend / MCP Engineer | F34: 3.1 | G34: 4 | H34: =WORKDAY(MAX($I$33),1,Holidays) -> 46377 | I34: =WORKDAY(H34,G34-1,Holidays) -> 46380 | J34: =IF(StatusDate<H34,0,MIN(1,NETWORKDAYS(H34,StatusDate,Holidays)/G34)) -> 1 | K34: 1 | L34: =K34-J34 -> 0 | M34: =IF(K34>=1,"Complete",IF(StatusDate>I34,"Overdue",IF(K34>0,IF(K34<J34-0.1,"Behind","In Progress"),IF(StatusDate>H34,"Late Start","Not Started")))) -> Complete | N34: 2 | O34: =G34*N34 -> 8 | P34: =O34*BlendedRate -> 2.56 | Q34: =P34*J34 -> 2.56 | R34: =P34*K34 -> 2.56 | S34: 2.76 | T34: ="S"&(INT((H34-ProjectStart)/SprintLen)+1) -> S5 | V34: =IF(AND($H34<=V$6+6,$I34>=V$6),1,"") | W34: =IF(AND($H34<=W$6+6,$I34>=W$6),1,"") | X34: =IF(AND($H34<=X$6+6,$I34>=X$6),1,"") | Y34: =IF(AND($H34<=Y$6+6,$I34>=Y$6),1,"") | Z34: =IF(AND($H34<=Z$6+6,$I34>=Z$6),1,"") | AA34: =IF(AND($H34<=AA$6+6,$I34>=AA$6),1,"") | AB34: =IF(AND($H34<=AB$6+6,$I34>=AB$6),1,"") | AC34: =IF(AND($H34<=AC$6+6,$I34>=AC$6),1,"") | ... AP34: =IF(AND($H34<=AP$6+6,$I34>=AP$6),1,"")
A35: 3.3 | B35: 2 | C35: Develop application discovery and status-query tools | D35: Read-only tool set | E35: Backend / MCP Engineer | F35: 3.2 | G35: 3 | H35: =WORKDAY(MAX($I$34),1,Holidays) -> 46384 | I35: =WORKDAY(H35,G35-1,Holidays) -> 46386 | J35: =IF(StatusDate<H35,0,MIN(1,NETWORKDAYS(H35,StatusDate,Holidays)/G35)) -> 1 | K35: 1 | L35: =K35-J35 -> 0 | M35: =IF(K35>=1,"Complete",IF(StatusDate>I35,"Overdue",IF(K35>0,IF(K35<J35-0.1,"Behind","In Progress"),IF(StatusDate>H35,"Late Start","Not Started")))) -> Complete | N35: 2 | O35: =G35*N35 -> 6 | P35: =O35*BlendedRate -> 1.92 | Q35: =P35*J35 -> 1.92 | R35: =P35*K35 -> 1.92 | S35: 2 | T35: ="S"&(INT((H35-ProjectStart)/SprintLen)+1) -> S6 | V35: =IF(AND($H35<=V$6+6,$I35>=V$6),1,"") | W35: =IF(AND($H35<=W$6+6,$I35>=W$6),1,"") | X35: =IF(AND($H35<=X$6+6,$I35>=X$6),1,"") | Y35: =IF(AND($H35<=Y$6+6,$I35>=Y$6),1,"") | Z35: =IF(AND($H35<=Z$6+6,$I35>=Z$6),1,"") | AA35: =IF(AND($H35<=AA$6+6,$I35>=AA$6),1,"") | AB35: =IF(AND($H35<=AB$6+6,$I35>=AB$6),1,"") | AC35: =IF(AND($H35<=AC$6+6,$I35>=AC$6),1,"") | ... AP35: =IF(AND($H35<=AP$6+6,$I35>=AP$6),1,"")
A36: 3.4 | B36: 2 | C36: Integrate SAP through approved APIs or connectors | D36: SAP integration proof of concept | E36: Backend / MCP Engineer / SAP SME | F36: 3.2 | G36: 4 | H36: =WORKDAY(MAX($I$34),1,Holidays) -> 46384 | I36: =WORKDAY(H36,G36-1,Holidays) -> 46387 | J36: =IF(StatusDate<H36,0,MIN(1,NETWORKDAYS(H36,StatusDate,Holidays)/G36)) -> 1 | K36: 1 | L36: =K36-J36 -> 0 | M36: =IF(K36>=1,"Complete",IF(StatusDate>I36,"Overdue",IF(K36>0,IF(K36<J36-0.1,"Behind","In Progress"),IF(StatusDate>H36,"Late Start","Not Started")))) -> Complete | N36: 3 | O36: =G36*N36 -> 12 | P36: =O36*BlendedRate -> 3.84 | Q36: =P36*J36 -> 3.84 | R36: =P36*K36 -> 3.84 | S36: 4.53 | T36: ="S"&(INT((H36-ProjectStart)/SprintLen)+1) -> S6 | V36: =IF(AND($H36<=V$6+6,$I36>=V$6),1,"") | W36: =IF(AND($H36<=W$6+6,$I36>=W$6),1,"") | X36: =IF(AND($H36<=X$6+6,$I36>=X$6),1,"") | Y36: =IF(AND($H36<=Y$6+6,$I36>=Y$6),1,"") | Z36: =IF(AND($H36<=Z$6+6,$I36>=Z$6),1,"") | AA36: =IF(AND($H36<=AA$6+6,$I36>=AA$6),1,"") | AB36: =IF(AND($H36<=AB$6+6,$I36>=AB$6),1,"") | AC36: =IF(AND($H36<=AC$6+6,$I36>=AC$6),1,"") | ... AP36: =IF(AND($H36<=AP$6+6,$I36>=AP$6),1,"")
A37: 3.5 | B37: 2 | C37: Integrate Oracle through approved APIs or connectors | D37: Oracle integration proof of concept | E37: Backend / MCP Engineer / Oracle SME | F37: 3.2 | G37: 4 | H37: =WORKDAY(MAX($I$34),1,Holidays) -> 46384 | I37: =WORKDAY(H37,G37-1,Holidays) -> 46387 | J37: =IF(StatusDate<H37,0,MIN(1,NETWORKDAYS(H37,StatusDate,Holidays)/G37)) -> 1 | K37: 0.7 | L37: =K37-J37 -> -0.3 | M37: =IF(K37>=1,"Complete",IF(StatusDate>I37,"Overdue",IF(K37>0,IF(K37<J37-0.1,"Behind","In Progress"),IF(StatusDate>H37,"Late Start","Not Started")))) -> Overdue | N37: 3 | O37: =G37*N37 -> 12 | P37: =O37*BlendedRate -> 3.84 | Q37: =P37*J37 -> 3.84 | R37: =P37*K37 -> 2.688 | S37: 3.63 | T37: ="S"&(INT((H37-ProjectStart)/SprintLen)+1) -> S6 | V37: =IF(AND($H37<=V$6+6,$I37>=V$6),1,"") | W37: =IF(AND($H37<=W$6+6,$I37>=W$6),1,"") | X37: =IF(AND($H37<=X$6+6,$I37>=X$6),1,"") | Y37: =IF(AND($H37<=Y$6+6,$I37>=Y$6),1,"") | Z37: =IF(AND($H37<=Z$6+6,$I37>=Z$6),1,"") | AA37: =IF(AND($H37<=AA$6+6,$I37>=AA$6),1,"") | AB37: =IF(AND($H37<=AB$6+6,$I37>=AB$6),1,"") | AC37: =IF(AND($H37<=AC$6+6,$I37>=AC$6),1,"") | ... AP37: =IF(AND($H37<=AP$6+6,$I37>=AP$6),1,"")
A38: 3.6 | B38: 2 | C38: Integrate QA and testing application interfaces | D38: QA/testing connector | E38: Backend / MCP Engineer / QA SME | F38: 3.2 | G38: 4 | H38: =WORKDAY(MAX($I$34),1,Holidays) -> 46384 | I38: =WORKDAY(H38,G38-1,Holidays) -> 46387 | J38: =IF(StatusDate<H38,0,MIN(1,NETWORKDAYS(H38,StatusDate,Holidays)/G38)) -> 1 | K38: 1 | L38: =K38-J38 -> 0 | M38: =IF(K38>=1,"Complete",IF(StatusDate>I38,"Overdue",IF(K38>0,IF(K38<J38-0.1,"Behind","In Progress"),IF(StatusDate>H38,"Late Start","Not Started")))) -> Complete | N38: 2 | O38: =G38*N38 -> 8 | P38: =O38*BlendedRate -> 2.56 | Q38: =P38*J38 -> 2.56 | R38: =P38*K38 -> 2.56 | S38: 2.66 | T38: ="S"&(INT((H38-ProjectStart)/SprintLen)+1) -> S6 | V38: =IF(AND($H38<=V$6+6,$I38>=V$6),1,"") | W38: =IF(AND($H38<=W$6+6,$I38>=W$6),1,"") | X38: =IF(AND($H38<=X$6+6,$I38>=X$6),1,"") | Y38: =IF(AND($H38<=Y$6+6,$I38>=Y$6),1,"") | Z38: =IF(AND($H38<=Z$6+6,$I38>=Z$6),1,"") | AA38: =IF(AND($H38<=AA$6+6,$I38>=AA$6),1,"") | AB38: =IF(AND($H38<=AB$6+6,$I38>=AB$6),1,"") | AC38: =IF(AND($H38<=AC$6+6,$I38>=AC$6),1,"") | ... AP38: =IF(AND($H38<=AP$6+6,$I38>=AP$6),1,"")
A39: 3.7 | B39: 2 | C39: Implement tool selection and parameter validation | D39: Tool-routing workflow | E39: AI / RAG Engineer | F39: 3.3 | G39: 3 | H39: =WORKDAY(MAX($I$35),1,Holidays) -> 46387 | I39: =WORKDAY(H39,G39-1,Holidays) -> 46392 | J39: =IF(StatusDate<H39,0,MIN(1,NETWORKDAYS(H39,StatusDate,Holidays)/G39)) -> 1 | K39: 1 | L39: =K39-J39 -> 0 | M39: =IF(K39>=1,"Complete",IF(StatusDate>I39,"Overdue",IF(K39>0,IF(K39<J39-0.1,"Behind","In Progress"),IF(StatusDate>H39,"Late Start","Not Started")))) -> Complete | N39: 2 | O39: =G39*N39 -> 6 | P39: =O39*BlendedRate -> 1.92 | Q39: =P39*J39 -> 1.92 | R39: =P39*K39 -> 1.92 | S39: 2 | T39: ="S"&(INT((H39-ProjectStart)/SprintLen)+1) -> S6 | V39: =IF(AND($H39<=V$6+6,$I39>=V$6),1,"") | W39: =IF(AND($H39<=W$6+6,$I39>=W$6),1,"") | X39: =IF(AND($H39<=X$6+6,$I39>=X$6),1,"") | Y39: =IF(AND($H39<=Y$6+6,$I39>=Y$6),1,"") | Z39: =IF(AND($H39<=Z$6+6,$I39>=Z$6),1,"") | AA39: =IF(AND($H39<=AA$6+6,$I39>=AA$6),1,"") | AB39: =IF(AND($H39<=AB$6+6,$I39>=AB$6),1,"") | AC39: =IF(AND($H39<=AC$6+6,$I39>=AC$6),1,"") | ... AP39: =IF(AND($H39<=AP$6+6,$I39>=AP$6),1,"")
A40: 3.8 | B40: 2 | C40: Add permission checks, timeouts, retries and error responses | D40: Resilient integration layer | E40: Backend / MCP Engineer | F40: 3.4, 3.5, 3.6 | G40: 3 | H40: =WORKDAY(MAX($I$36,$I$37,$I$38),1,Holidays) -> 46391 | I40: =WORKDAY(H40,G40-1,Holidays) -> 46393 | J40: =IF(StatusDate<H40,0,MIN(1,NETWORKDAYS(H40,StatusDate,Holidays)/G40)) -> 1 | K40: 0.6 | L40: =K40-J40 -> -0.4 | M40: =IF(K40>=1,"Complete",IF(StatusDate>I40,"Overdue",IF(K40>0,IF(K40<J40-0.1,"Behind","In Progress"),IF(StatusDate>H40,"Late Start","Not Started")))) -> Overdue | N40: 2 | O40: =G40*N40 -> 6 | P40: =O40*BlendedRate -> 1.92 | Q40: =P40*J40 -> 1.92 | R40: =P40*K40 -> 1.152 | S40: 1.2 | T40: ="S"&(INT((H40-ProjectStart)/SprintLen)+1) -> S6 | V40: =IF(AND($H40<=V$6+6,$I40>=V$6),1,"") | W40: =IF(AND($H40<=W$6+6,$I40>=W$6),1,"") | X40: =IF(AND($H40<=X$6+6,$I40>=X$6),1,"") | Y40: =IF(AND($H40<=Y$6+6,$I40>=Y$6),1,"") | Z40: =IF(AND($H40<=Z$6+6,$I40>=Z$6),1,"") | AA40: =IF(AND($H40<=AA$6+6,$I40>=AA$6),1,"") | AB40: =IF(AND($H40<=AB$6+6,$I40>=AB$6),1,"") | AC40: =IF(AND($H40<=AC$6+6,$I40>=AC$6),1,"") | ... AP40: =IF(AND($H40<=AP$6+6,$I40>=AP$6),1,"")
...

Sheet Milestones
A1: Milestones & Phase Gates
A2: Baseline = end of each 4-week month · Forecast and Actual dates are inputs
A4: ID | B4: Milestone | C4: Target Week | D4: Baseline Date | E4: Forecast Date | F4: Actual Date | G4: Variance (work days) | H4: Status | I4: Acceptance Evidence | J4: Exit Criteria
A5: M1 | B5: Architecture approved | C5: Week 4 | D5: ='WBS Schedule'!I19 -> 46342 | E5: ='WBS Schedule'!I19 -> 46342 | F5: 46342 | G5: =IF(F5<>"",IF(F5>D5,NETWORKDAYS(D5,F5,Holidays)-1,-(NETWORKDAYS(F5,D5,Holidays)-1)),IF(E5>D5,NETWORKDAYS(D5,E5,Holidays)-1,-(NETWORKDAYS(E5,D5,Holidays)-1))) -> 0 | H5: =IF(F5<>"","Achieved",IF(G5>0,"At Risk",IF(StatusDate>D5,"Overdue","On Track"))) -> Achieved | I5: Signed-off requirements and design | J5: Stakeholders approve the MVP scope, architecture, security approach, initial use cases and access requirements.
A6: M2 | B6: AI assistant MVP | C6: Week 8 | D6: ='WBS Schedule'!I31 -> 46371 | E6: ='WBS Schedule'!I31 -> 46371 | F6: 46370 | G6: =IF(F6<>"",IF(F6>D6,NETWORKDAYS(D6,F6,Holidays)-1,-(NETWORKDAYS(F6,D6,Holidays)-1)),IF(E6>D6,NETWORKDAYS(D6,E6,Holidays)-1,-(NETWORKDAYS(E6,D6,Holidays)-1))) -> -1 | H6: =IF(F6<>"","Achieved",IF(G6>0,"At Risk",IF(StatusDate>D6,"Overdue","On Track"))) -> Achieved | I6: Grounded answers from approved documents | J6: A user can ask questions about approved sample documentation and receive relevant, source-grounded answers through the chat interface.
A7: M3 | B7: Application integrations | C7: Week 12 | D7: ='WBS Schedule'!I43 -> 46401 | E7: 46409 | G7: =IF(F7<>"",IF(F7>D7,NETWORKDAYS(D7,F7,Holidays)-1,-(NETWORKDAYS(F7,D7,Holidays)-1)),IF(E7>D7,NETWORKDAYS(D7,E7,Holidays)-1,-(NETWORKDAYS(E7,D7,Holidays)-1))) -> 6 | H7: =IF(F7<>"","Achieved",IF(G7>0,"At Risk",IF(StatusDate>D7,"Overdue","On Track"))) -> At Risk | I7: Demonstrable end-to-end test workflows | J7: The assistant answers knowledge questions and executes approved, read-only operations against available test integrations (SAP/Oracle scope subject to API access, licensing and environment readiness).
A8: M4 | B8: Release candidate | C8: Week 16 | D8: ='WBS Schedule'!I55 -> 46430 | E8: 46434 | G8: =IF(F8<>"",IF(F8>D8,NETWORKDAYS(D8,F8,Holidays)-1,-(NETWORKDAYS(F8,D8,Holidays)-1)),IF(E8>D8,NETWORKDAYS(D8,E8,Holidays)-1,-(NETWORKDAYS(E8,D8,Holidays)-1))) -> 2 | H8: =IF(F8<>"","Achieved",IF(G8>0,"At Risk",IF(StatusDate>D8,"Overdue","On Track"))) -> At Risk | I8: Security, QA and evaluation reports | J8: Critical security and functional defects are resolved, agreed evaluation thresholds are met, and release risks are documented.
A9: M5 | B9: Pilot accepted | C9: Week 20 | D9: ='WBS Schedule'!I68 -> 46458 | E9: 46458 | G9: =IF(F9<>"",IF(F9>D9,NETWORKDAYS(D9,F9,Holidays)-1,-(NETWORKDAYS(F9,D9,Holidays)-1)),IF(E9>D9,NETWORKDAYS(D9,E9,Holidays)-1,-(NETWORKDAYS(E9,D9,Holidays)-1))) -> 0 | H9: =IF(F9<>"","Achieved",IF(G9>0,"At Risk",IF(StatusDate>D9,"Overdue","On Track"))) -> On Track | I9: UAT sign-off and handover | J9: Business stakeholders accept the pilot results, operational ownership is assigned, and production deployment is approved or has a documented readiness decision.

Sheet Team & Resources
A1: Team Structure & Resourcing
A2: Blue values are editable · Cost = Headcount × Allocation × Rate × Working days
A4: Role | B4: Named Resources (demo) | C4: Headcount | D4: Allocation (FTE %) | E4: Day Rate (₹ L) | F4: Effective FTE | G4: Cost over Project (₹ L) | H4: Responsibilities
A5: Project Manager / Product Owner | B5: Ananya Rao; Vikram Desai | C5: 2 | D5: 1 | E5: 0.42 | F5: =C5*D5 -> 2 | G5: =F5*E5*'WBS Schedule'!$G$7 -> 84 | H5: Scope, priorities, stakeholders, risks and acceptance
A6: Solution Architect | B6: Karthik Iyer | C6: 1 | D6: 0.6 | E6: 0.45 | F6: =C6*D6 -> 0.6 | G6: =F6*E6*'WBS Schedule'!$G$7 -> 27 | H6: Architecture decisions, integration contracts, handover
A7: AI / RAG Engineer | B7: Priya Nair; Arjun Mehta | C7: 2 | D7: 1 | E7: 0.36 | F7: =C7*D7 -> 2 | G7: =F7*E7*'WBS Schedule'!$G$7 -> 72 | H7: GPT-5, Foundry IQ, prompts, retrieval and evaluation
A8: Backend / MCP Engineer | B8: Rohan Kulkarni; Sneha Joshi | C8: 2 | D8: 1 | E8: 0.32 | F8: =C8*D8 -> 2 | G8: =F8*E8*'WBS Schedule'!$G$7 -> 64 | H8: MCP tools, APIs, application connectors and orchestration
A9: Frontend Engineer | B9: Meera Pillai | C9: 1 | D9: 1 | E9: 0.28 | F9: =C9*D9 -> 1 | G9: =F9*E9*'WBS Schedule'!$G$7 -> 28 | H9: Chat UI, application dashboard and user experience
A10: QA Engineer | B10: Divya Shetty | C10: 1 | D10: 1 | E10: 0.26 | F10: =C10*D10 -> 1 | G10: =F10*E10*'WBS Schedule'!$G$7 -> 26 | H10: Test strategy, evaluation datasets, regression and UAT support
A11: Security Engineer | B11: Aditya Bose | C11: 1 | D11: 0.5 | E11: 0.38 | F11: =C11*D11 -> 0.5 | G11: =F11*E11*'WBS Schedule'!$G$7 -> 19 | H11: Entra ID, authorization, AI security testing
A12: DevOps Engineer | B12: Farhan Qureshi | C12: 1 | D12: 0.8 | E12: 0.3 | F12: =C12*D12 -> 0.8 | G12: =F12*E12*'WBS Schedule'!$G$7 -> 24 | H12: Azure provisioning, CI/CD, observability
A13: SAP / Oracle / QA Application SMEs | B13: SAP CoE; Oracle DBA team; QA tooling owners | C13: 3 | D13: 0.25 | E13: 0.35 | F13: =C13*D13 -> 0.75 | G13: =F13*E13*'WBS Schedule'!$G$7 -> 26.25 | H13: Use cases, API access, business validation
A14: Total | C14: =SUM(C5:C13) -> 14 | F14: =SUM(F5:F13) -> 10.65 | G14: =SUM(G5:G13) -> 370.25 | H14: Core team of ~10 named members plus shared SMEs (source plan: 7–10 core)

Sheet Workstreams
A1: Cross-Functional Workstreams
A2: Activities that span multiple phases; Start/End week are inputs
A4: Workstream | B4: Lead | C4: Start Week | D4: End Week | E4: Key Outputs | F4: W1 | G4: W2 | H4: W3 | I4: W4 | J4: W5 | K4: W6 | L4: W7 | M4: W8 | N4: W9 | O4: W10 | P4: W11 | Q4: W12 | R4: W13 | S4: W14 | T4: W15 | U4: W16 | V4: W17 | W4: W18 | X4: W19 | Y4: W20 | Z4: W21
